<?xml version="1.0" ?>
<!-- =================================================================================== -->
<!-- |    This document was autogenerated by xacro from arna_base.xacro                | -->
<!-- |    EDITING THIS FILE BY HAND IS NOT RECOMMENDED                                 | -->
<!-- =================================================================================== -->
<robot name="arna_base" xmlns:xacro="http://www.ros.org/wiki/xacro">
  <!-- ros_control plugin -->
  <gazebo>
    <plugin filename="libgazebo_ros_control.so" name="gazebo_ros_control">
      <robotNamespace>/arna_base</robotNamespace>
      <!-- <robotSimType>gazebo_ros_control/DefaultRobotHWSim</robotSimType> -->
    </plugin>
  </gazebo>
  <gazebo reference="fl_link">
    <mu1 value="100000.0"/>
    <mu2 value="100000.0"/>
    <!--   	<fdir1>0 1 0</fdir1>
  	<minDepth>0.01</minDepth>
	<mu1 value="0.0"/>
    <mu2 value="0.0"/> -->
    <!--     <kp value="10000000.0" />
    <kd value="1.0" />  -->
    <material>Gazebo/Grey</material>
  </gazebo>
  <gazebo reference="fr_link">
    <mu1 value="100000.0"/>
    <mu2 value="100000.0"/>
    <!--   	<fdir1>0 1 0</fdir1>
  	<minDepth>0.01</minDepth>
	<mu1 value="0.0"/>
    <mu2 value="0.0"/> -->
    <!--     <kp value="10000000.0" />
    <kd value="1.0" />  -->
    <material>Gazebo/Grey</material>
  </gazebo>
  <gazebo reference="bl_link">
    <mu1 value="100000.0"/>
    <mu2 value="100000.0"/>
    <!--  	<fdir1>0 1 0</fdir1>
  	<minDepth>0.01</minDepth>
	<mu1 value="0.0"/>
    <mu2 value="0.0"/> -->
    <!--     <kp value="10000000.0" />
    <kd value="1.0" />  -->
    <material>Gazebo/Grey</material>
  </gazebo>
  <gazebo reference="br_link">
    <mu1 value="100000.0"/>
    <mu2 value="100000.0"/>
    <!--   	<fdir1>0 1 0</fdir1>
  	<minDepth>0.01</minDepth>
	<mu1 value="0.0"/>
    <mu2 value="0.0"/> -->
    <!--     <kp value="10000000.0" />
    <kd value="1.0" />  -->
    <material>Gazebo/Grey</material>
  </gazebo>
  <!-- <link name="world"/> -->
  <link name="dummy_link"/>
  <joint name="fixed" type="fixed">
    <parent link="dummy_link"/>
    <child link="base_link"/>
  </joint>
  <link name="base_link">
    <inertial>
      <origin rpy="0 0 0" xyz="0 0 0"/>
      <!-- xyz = "-0.0035731875614072 0.242136118748611 -0.0486968548113747"-->
      <mass value="127.979476827935"/>
      <inertia ixx="8.92508720014459" ixy="0.386969604653879" ixz="-0.183135216071402" iyy="9.43135313907935" iyz="0.55988655947468" izz="9.13799322069061"/>
    </inertial>
    <visual>
      <origin rpy="0 0 0" xyz="0 0 0"/>
      <geometry>
        <mesh filename="package://arna_base_description/meshes/base_link.STL"/>
      </geometry>
      <material name="">
        <color rgba="0.752941176470588 0.752941176470588 0.752941176470588 1"/>
      </material>
    </visual>
    <collision>
      <origin rpy="0 0 0" xyz="0 0 0"/>
      <geometry>
        <mesh filename="package://arna_base_description/meshes/base_link.STL"/>
      </geometry>
    </collision>
  </link>
  <joint name="fl_joint" type="continuous">
    <origin rpy="1.5708 -0.62539 -1.5708" xyz="-0.37084 0.31317 0.1016"/>
    <parent link="base_link"/>
    <child link="fl_link"/>
    <axis xyz="0 0 -1"/>
    <!--0 0 -1-->
    <!--     <limit
      effort="30"
      velocity="1.0" /> -->
  </joint>
  <link name="fl_link">
    <inertial>
      <origin rpy="0 0 0" xyz="-2.3929E-05 -1.0301E-07 0.05357"/>
      <!--xyz = -->
      <mass value="5.5136"/>
      <inertia ixx="0.012979" ixy="1.3657E-11" ixz="-3.6507E-09" iyy="0.012979" iyz="-2.742E-09" izz="0.017507"/>
    </inertial>
    <visual>
      <origin rpy="0 0 0" xyz="0 0 0"/>
      <!-- xyz="$0 0 {bodylen/2}" if cylinder is used -->
      <geometry>
        <!-- <cylinder radius="${width}" length="${bodylen}"/> -->
        <mesh filename="package://arna_base_description/meshes/fl_link.STL"/>
      </geometry>
      <material name="">
        <color rgba="0.89804 0.91765 0.92941 1"/>
      </material>
    </visual>
    <collision>
      <origin rpy="0 0 0" xyz="0 0 0.050772"/>
      <geometry>
        <!-- <cylinder radius="${width}" length="${bodylen}"/> -->
        <sphere radius="0.101478"/>
        <!--         <mesh
          filename="package://arna_base_description/meshes/fl_link.STL" /> -->
      </geometry>
    </collision>
  </link>
  <joint name="fr_joint" type="continuous">
    <origin rpy="1.5708  0 -1.5708" xyz="0.37084 0.31317 0.1016"/>
    <parent link="base_link"/>
    <child link="fr_link"/>
    <axis xyz="0 0 -1"/>
    <!--0 0 -1-->
    <!--     <limit
      effort="30"
      velocity="1.0" /> -->
  </joint>
  <link name="fr_link">
    <inertial>
      <origin rpy="0 0 0" xyz="-2.3976E-05 -1.0318E-09 -0.05357"/>
      <!-- xyz= -->
      <mass value="5.5137"/>
      <inertia ixx="0.01298" ixy="1.3643E-13" ixz="-3.6682E-09" iyy="0.01298" iyz="-2.7766E-10" izz="0.017507"/>
    </inertial>
    <visual>
      <origin rpy="0 0 0" xyz="0 0 0"/>
      <!-- xyz="0 0 ${-bodylen/2}" if cylinder is used -->
      <geometry>
        <!-- <cylinder radius="${width}" length="${bodylen}"/> -->
        <mesh filename="package://arna_base_description/meshes/fr_link.STL"/>
      </geometry>
      <material name="">
        <color rgba="0.89804 0.91765 0.92941 1"/>
      </material>
    </visual>
    <collision>
      <origin rpy="0 0 0" xyz="0 0 -0.050772"/>
      <geometry>
        <!-- <cylinder radius="${width}" length="${bodylen}"/> -->
        <sphere radius="0.101478"/>
        <!-- <mesh
          filename="package://arna_base_description/meshes/fr_link.STL" /> -->
      </geometry>
    </collision>
  </link>
  <joint name="bl_joint" type="continuous">
    <origin rpy="1.5708 -0.79346 1.5708" xyz="-0.37084 -0.31317 0.1016"/>
    <parent link="base_link"/>
    <child link="bl_link"/>
    <axis xyz="0 0 1"/>
    <!--0 0 1-->
    <!--     <limit
      effort="30"
      velocity="1.0" /> -->
  </joint>
  <link name="bl_link">
    <inertial>
      <origin rpy="0 0 0" xyz="-2.3976E-05 -1.0318E-09 -0.05357"/>
      <mass value="5.5137"/>
      <inertia ixx="0.01298" ixy="1.3644E-13" ixz="-3.6682E-09" iyy="0.01298" iyz="-2.7766E-10" izz="0.017507"/>
    </inertial>
    <visual>
      <origin rpy="0 0 0" xyz="0 0 0"/>
      <!-- xyz="$0 0 {-bodylen/2}" if cylinder is used -->
      <geometry>
        <!-- <cylinder radius="${width}" length="${bodylen}"/> -->
        <mesh filename="package://arna_base_description/meshes/bl_link.STL"/>
      </geometry>
      <material name="">
        <color rgba="0.89804 0.91765 0.92941 1"/>
      </material>
    </visual>
    <collision>
      <origin rpy="0 0 0" xyz="0 0 -0.050772 "/>
      <geometry>
        <!-- <cylinder radius="${width}" length="${bodylen}"/> -->
        <sphere radius="0.101478"/>
        <!--         <mesh
          filename="package://arna_base_description/meshes/bl_link.STL" /> -->
      </geometry>
    </collision>
  </link>
  <joint name="br_joint" type="continuous">
    <origin rpy="1.5708 -0.62539 1.5708" xyz="0.37085 -0.31317 0.1016"/>
    <parent link="base_link"/>
    <child link="br_link"/>
    <axis xyz="0 0 1"/>
    <!--0 0 1-->
    <!--     <limit
      effort="30"
      velocity="1.0" /> -->
  </joint>
  <link name="br_link">
    <inertial>
      <origin rpy="0 0 0" xyz="-2.3929E-05 -1.0301E-07 0.05357"/>
      <mass value="5.5136"/>
      <inertia ixx="0.012979" ixy="1.3657E-11" ixz="-3.6507E-09" iyy="0.012979" iyz="-2.742E-09" izz="0.017507"/>
    </inertial>
    <visual>
      <origin rpy="0 0 0" xyz="0 0 0"/>
      <!-- xyz="$0 0 {bodylen/2}" if cylinder is used -->
      <geometry>
        <!-- <cylinder radius="${width}" length="${bodylen}"/> -->
        <mesh filename="package://arna_base_description/meshes/br_link.STL"/>
      </geometry>
      <material name="">
        <color rgba="0.89804 0.91765 0.92941 1"/>
      </material>
    </visual>
    <collision>
      <origin rpy="0 0 0" xyz="0 0 0.050772 "/>
      <geometry>
        <!-- <cylinder radius="${width}" length="${bodylen}"/> -->
        <sphere radius="0.101478"/>
        <!-- <mesh
          filename="package://arna_base_description/meshes/br_link.STL" /> -->
      </geometry>
    </collision>
  </link>
  <joint name="hokuyo_joint" type="fixed">
    <axis xyz="0 0 0"/>
    <origin rpy="0 0 1.5708" xyz="0 0.5 0.3"/>
    <parent link="base_link"/>
    <child link="hokuyo_link"/>
  </joint>
  <!-- Hokuyo Laser -->
  <link name="hokuyo_link">
    <collision>
      <origin rpy="0 0 0" xyz="0 0 0"/>
      <geometry>
        <box size="0.1 0.1 0.1"/>
      </geometry>
    </collision>
    <visual>
      <origin rpy="0 0 0" xyz="0 0 0"/>
      <geometry>
        <mesh filename="package://arna_base_description/meshes/hokuyo.dae"/>
      </geometry>
    </visual>
    <inertial>
      <mass value="1e-5"/>
      <origin rpy="0 0 0" xyz="0 0 0"/>
      <inertia ixx="1e-6" ixy="0" ixz="0" iyy="1e-6" iyz="0" izz="1e-6"/>
    </inertial>
  </link>
  <gazebo reference="hokuyo_link">
      <sensor name="head_hokuyo_sensor" type="gpu_ray">
         <pose>0 0 0 0 0 0</pose>
         <visualize>false</visualize>
         <update_rate>40</update_rate>
         <ray>
            <scan>
               <horizontal>
                  <samples>720</samples>
                  <resolution>1</resolution>
                  <min_angle>-1.570796</min_angle>
                  <max_angle>1.570796</max_angle>
                  <!--
                  <min_angle>-2.26889</min_angle>
                  <max_angle>2.268899</max_angle>
                  -->
               </horizontal>
            </scan>
            <range>
               <min>0.10</min>
               <max>30.0</max>
               <resolution>0.01</resolution>
            </range>
            <noise>
               <type>gaussian</type>
               <mean>0.0</mean>
               <stddev>0.01</stddev>
            </noise>
         </ray>
         <plugin filename="libgazebo_ros_gpu_laser.so" name="gazebo_ros_head_hokuyo_controller">
            <topicName>/scan</topicName>
            <frameName>hokuyo_link</frameName>
         </plugin>
      </sensor>
   </gazebo>
  <transmission name="tran1">
    <type>transmission_interface/SimpleTransmission</type>
    <joint name="fl_joint">
      <hardwareInterface>hardware_interface/VelocityJointInterface</hardwareInterface>
    </joint>
    <!--hardware_interface/EffortJointInterface-->
    <actuator name="motor1">
      <hardwareInterface>VelocityJointInterface</hardwareInterface>
      <mechanicalReduction>1</mechanicalReduction>
    </actuator>
  </transmission>
  <transmission name="tran2">
    <type>transmission_interface/SimpleTransmission</type>
    <joint name="fr_joint">
      <hardwareInterface>hardware_interface/VelocityJointInterface</hardwareInterface>
    </joint>
    <actuator name="motor2">
      <hardwareInterface>VelocityJointInterface</hardwareInterface>
      <mechanicalReduction>1</mechanicalReduction>
    </actuator>
  </transmission>
  <transmission name="tran3">
    <type>transmission_interface/SimpleTransmission</type>
    <joint name="bl_joint">
      <hardwareInterface>hardware_interface/VelocityJointInterface</hardwareInterface>
    </joint>
    <actuator name="motor3">
      <hardwareInterface>VelocityJointInterface</hardwareInterface>
      <mechanicalReduction>1</mechanicalReduction>
    </actuator>
  </transmission>
  <transmission name="tran4">
    <type>transmission_interface/SimpleTransmission</type>
    <joint name="br_joint">
      <hardwareInterface>hardware_interface/VelocityJointInterface</hardwareInterface>
    </joint>
    <actuator name="motor4">
      <hardwareInterface>VelocityJointInterface</hardwareInterface>
      <mechanicalReduction>1</mechanicalReduction>
    </actuator>
  </transmission>
</robot>
